---
layout: post
category: scala
date: 2015-02-04 22:11:38 UTC
title: Scala基础之try...catch...finally
tags: [异常处理, 字节]
permalink: /scala/try-catch/
key: 9fc1d12984edc4fbd228195de9084ada
---


# 问题
今天，一同事在写一个异常捕获的时候，突然抛出以下代码，让我们研究返回值。

```scala
def getResult: Int = try {
    println("try执行了吗？"）
    return 1
} finally {
    println("finally执行了吗？"）
    return 3
}
```
首先上面那种写法就很奇怪，因为不管是在Scala还是Java中finally一般都是没有返回值(确切的说返回值是Unit)的，如果显示声明了return, 那么返回值应该是多少了。答案是此时返回值应该是<b style="color:red">finally中return的值</b>。
如果try中有异常而finally中没有异常且显示的声明了return，此时整个流程怎么走？
如果finally有异常，整个流程又怎么走？
本文会对Scala中detry...catch...finally的整个语法进行梳理，如有不对的地方还请大家指出。
  
# 解决
首先为什么上面的表达式返回的是<b style="color:red">3</b>，都说源码面前，了无秘密。通过[Java Decompiler](http://jd.benow.ca/)将上面的Scala代码对应的class文件反解，就可以看到如下代码:

```java
public int getResult() {
    try { Predef..MODULE$.println("try 执行了吗？ ");

      return 3;
    }
    finally
    {
      Predef..MODULE$.println(" finally 执行了吗");
    }return 3;
  }
```
显然，finally中的代码已经改变原来的方法的执行流程，可以简单的理解为在Scala中

```try { b } catch e1 finally e2```

<b style="color:red">b的类型是try表达式的期望类型, e1实际上是一个偏函数: scala.PartialFunction[scala.Throwable, pt], pt <: b, 而e2的类型则是Unit</b>。
所以此时的控制流程又回到了try表达式中，因为此时<b style="color:red">只有try{}才可以返回满足方法签名类型的返回值</b>，也就是Int。
同时会将finally中的'返回值'作为最终的值返回。

下面针对不同情况下，try...catch...finally的处理进行解释:

首先明确的一点是finally无论如何都会执行，no matter what happens beforehand in the try block, always run this code.

<1> 计算b的过程中没有异常
    
如果在计算表达式e的过程中又抛出异常，那么整个表达式会中止，并且抛出异常(e表达式中包含的异常)

如果在计算表达式的e的过程中没有抛出异常，那么b就是整个表达式的返回值

<2> 计算b的过程中有异常(e中的表达式仍然会被计算)

如果e的计算过程也抛出异常，那么表达式会中止并且e过程中的异常被抛出

如果e的计算过程中没有抛出异常，那么原来b中的异常会在e计算完成之后再次抛出(关于这一点比较恐怖的是<b style="color:



```scala
  def get11: Int = try {
    throw new RuntimeException
  } finally {
    return 3
  }
```
上面这段代码还是会返回3。

最后贴一段[JLS 14.17 The return Statement](http://docs.oracle.com/javase/specs/jls/se5.0/html/statements.html#14.17)

> The preceding descriptions say "attempts to transfer control" rather than just "transfers control" because if there are any try statements (§14.20) within the method or 
> constructor whose try blocks or catch clauses contain the return statement, then any finally clauses of those try statements will be executed, in order, innermost to 
> outermost, before control is transferred to the invoker of the method or constructor. Abrupt completion of a finally clause can disrupt the transfer of control initiated by a 
> return statement.

简单的解释就是：如果在方法或构造器中包含return，那么try表达式中的finally中的语句会依次执行然后将流程返回给该方法或者是构造器的调用者。如果在finally的执行中，出现任何意外情况，那么流程的返回过程就会出现意外。


# 结语
我们最开始学习Java时候，各种教材都会讲到在定义Java变量名时我们尽量不要采用生僻的命名，这条规则同样适用于这里。

关于这个问题在[Stackoverlflow](http://stackoverflow.com/questions/65035/does-finally-always-execute-in-java)有很多讨论涉及知识点也很多。总之一句话，我们尽量不要使用各种语法比较妖孽的地方，就比如说finally本来就不该出现return，它通常会用于处理异常抛出之后的收尾工作，比如说关闭流等。